<!-- This is a clean version of diff_catbot.urdf containing no Camera nor Laser controllers plugin -->
<?xml version="1.0" ?>
<robot name="differential_drive_catbot">
        <!-- This is a fictitious link, falling right below the center of mass of the robot, and acting as a projection of it on the ground.-->
        <link name="base_footprint">
                <inertial>
                        <mass value="0.0001"/>
                        <origin xyz="0 0 0"/>
                        <inertia ixx="0.0001" ixy="0.0" ixz="0.0" iyy="0.0001" iyz="0.0" izz="0.0001"/>
                </inertial>
        </link>
        <!-- Joint to connect the fictitious link to the actual chassis of the robot -->
        <joint name="base_footprint_joint" type="fixed">
                <origin rpy="0 0 -1.570796327" xyz="0 0 0.125"/>
                <parent link="base_footprint"/>
                <child link="base_link"/>
        </joint>
        <!-- Actual chassis link of the robot -->
        <link name="base_link">
                <inertial>
                        <origin xyz="0 0 0" rpy="0 0 0" />
                        <mass value="3" />
                        <inertia ixx="0.144425345253922" ixy="0" ixz="0" iyy="0.152767714510505" iyz="-0.00237163573657069" izz="0.005" />
                </inertial>
                <visual>
                        <origin xyz="0 0 0" rpy="0 0 0" />
                        <geometry>
                                <mesh filename="package://catbot_description/meshes/diff_catbot/base_link.STL" />
                        </geometry>
                        <material name="">
                                <color rgba="1 0 0 1" />
                        </material>
                </visual>
                <collision>
                        <origin xyz="0 0 0" rpy="0 0 0" />
                        <geometry>
                                <mesh filename="package://catbot_description/meshes/diff_catbot/base_link.STL" />
                        </geometry>
                </collision>
        </link>
        <!-- Right wheel link -->
        <link name="right_wheel">
                <inertial>
                        <origin xyz="0 0 -0.019494" rpy="0 0 0" />
                        <mass value="2" />
                        <inertia ixx="0.00017099" ixy="0" ixz="0" iyy="0.00017099" iyz="0" izz="0.00031986" />
                </inertial>
                <visual>
                        <origin xyz="0 0 0" rpy="0 0 0" />
                        <geometry>
                                <mesh filename="package://catbot_description/meshes/diff_catbot/right_wheel.STL" />
                        </geometry>
                        <material name="">
                                <color rgba="0 0 0 1" />
                        </material>
                </visual>
                <collision>
                        <origin xyz="0 0 0" rpy="0 0 0" />
                        <geometry>
                                <mesh filename="package://catbot_description/meshes/diff_catbot/right_wheel.STL" />
                        </geometry>
                </collision>
        </link>
        <!-- Right wheel joint, this joint is commanded with velocity to cause the wheel to rotate -->
        <joint name="right_motor" type="continuous">
                <origin xyz="0.15697 -0.073269 -0.041165" rpy="1.5708 0 -1.5708" />
                <parent link="base_link" />
                <child link="right_wheel" />
                <axis xyz="0 0 1" />
                <limit effort="10000" velocity="100" />
                <dynamics damping="0" friction="0" />
        </joint>
        <!-- Left wheel link -->
        <link name="left_wheel">
                <inertial>
                        <origin xyz="0 0 0.019494" rpy="0 0 0" />
                        <mass value="2" />
                        <inertia ixx="0.00017099" ixy="0" ixz="0" iyy="0.00017099" iyz="0" izz="0.00031986" />
                </inertial>
                <visual>
                        <origin xyz="0 0 0" rpy="0 0 0" />
                        <geometry>
                                <mesh filename="package://catbot_description/meshes/diff_catbot/left_wheel.STL" />
                        </geometry>
                        <material name="">
                                <color rgba="0 0 0 1" />
                        </material>
                </visual>
                <collision>
                        <origin xyz="0 0 0" rpy="0 0 0" />
                        <geometry>
                                <mesh filename="package://catbot_description/meshes/diff_catbot/left_wheel.STL" />
                        </geometry>
                </collision>
        </link>
        <!-- Left wheel joint, this joint is commanded with velocity to cause the wheel to rotate -->
        <joint name="left_motor" type="continuous">
                <origin xyz="-0.15697 -0.073269 -0.041165" rpy="1.5708 0 -1.5708" />
                <parent link="base_link" />
                <child link="left_wheel" />
                <axis xyz="0 0 1" />
                <limit effort="10000" velocity="100" />
                <dynamics damping="0" friction="0" />
        </joint>
        <!-- Caster Wheel Joint and Link -->
        <joint name="ball_and_socket" type="fixed">
                <origin xyz="0 0.20508 -0.11627" rpy="1.5708 0 -1.5708" />
                <parent link="base_link" />
                <child link="caster_wheel" />
        </joint>
        <link name="caster_wheel">
                <inertial>
                        <origin xyz="0 0 0" rpy="0 0 0" />
                        <mass value="0.0035914" />
                        <inertia ixx="1.2965E-07" ixy="0" ixz="0" iyy="1.2965E-07" iyz="0" izz="1.2965E-07" />
                </inertial>
                <visual>
                        <origin xyz="0 0 0" rpy="0 0 0" />
                        <geometry>
                                <mesh filename="package://catbot_description/meshes/diff_catbot/caster_wheel.STL" />
                        </geometry>
                        <material name="">
                                <color rgba="0 0 0 1" />
                        </material>
                </visual>
                <collision>
                        <origin xyz="0 0 0" rpy="0 0 0" />
                        <geometry>
                                <mesh filename="package://catbot_description/meshes/diff_catbot/caster_wheel.STL" />
                        </geometry>
                </collision>
        </link>
        <!-- Camera Link -->
        <link name="camera">
                <inertial>
                        <origin xyz="0 0 0" rpy="0 0 0" />
                        <mass value="0.028578" />
                        <inertia ixx="2.1737E-05" ixy="0" ixz="0" iyy="2.037E-06" iyz="0" izz="2.0659E-05" />
                </inertial>
                <visual>
                        <origin xyz="0 0 0" rpy="0 0 0" />
                        <geometry>
                                <mesh filename="package://catbot_description/meshes/diff_catbot/camera.STL" />
                        </geometry>
                        <material name="">
                                <color rgba="0 0 1 1" />
                        </material>
                </visual>
                <collision>
                        <origin xyz="0 0 0" rpy="0 0 0" />
                        <geometry>
                                <mesh filename="package://catbot_description/meshes/diff_catbot/camera.STL" />
                        </geometry>
                </collision>
        </link>
        <!-- Camera Joint to connect the camera to the chassis -->
        <joint name="camera_joint" type="fixed">
                <origin xyz="0 0.27409 -0.039719" rpy="0 0 1.5708" />
                <parent link="base_link" />
                <child link="camera" />
        </joint>
        <!-- Laser Scanner Link -->
        <link name="laser_scanner">
                <inertial>
                        <origin xyz="0 0 0" rpy="0 0 0" />
                        <mass value="0.6525" />
                        <inertia ixx="0.0011739" ixy="0" ixz="0" iyy="0.00060212" iyz="0" izz="0.0015305" />
                </inertial>
                <visual>
                        <origin xyz="0 0 0" rpy="0 0 0" />
                        <geometry>
                                <mesh filename="package://catbot_description/meshes/diff_catbot/laser_scanner.STL" />
                        </geometry>
                        <material name="">
                                <color rgba="1 1 0 1" />
                        </material>
                </visual>
                <collision>
                        <origin xyz="0 0 0" rpy="0 0 0" />
                        <geometry>
                                <mesh filename="package://catbot_description/meshes/diff_catbot/laser_scanner.STL" />
                        </geometry>
                </collision>
        </link>
        <!-- Laser Scanner Joint to connect the laser scanner to the chassis -->
        <joint name="laser_scanner_joint" type="fixed">
                <origin xyz="0 0.026147 0.11309" rpy="0 0 1.5708" />
                <parent link="base_link" />
                <child link="laser_scanner" />
        </joint>
        <!-- Transmissions are important for abstracting the connection between urdf model joints and actuators (wheter simulated or actual) -->
        <!-- Left wheel transmission -->
        <transmission name="left_motor_transmission">
                <type>transmission_interface/SimpleTransmission</type>
                <joint name="left_motor">
                        <hardwareInterface>VelocityJointInterface</hardwareInterface>
                </joint>
                <actuator name="left_joint_motor">
                        <hardwareInterface>VelocityJointInterface</hardwareInterface>
                        <mechanicalReduction>1</mechanicalReduction>
                </actuator>
        </transmission>
        <!-- Right wheel transmission -->
        <transmission name="right_motor_transmission">
                <type>transmission_interface/SimpleTransmission</type>
                <joint name="right_motor">
                        <hardwareInterface>VelocityJointInterface</hardwareInterface>
                </joint>
                <actuator name="right_joint_motor">
                        <hardwareInterface>VelocityJointInterface</hardwareInterface>
                        <mechanicalReduction>1</mechanicalReduction>
                </actuator>
        </transmission>
        <!-- gazebo tag is used to add simulation properties to a URDF file -->
        <gazebo reference="base_footprint">
                <turnGravityOff>false</turnGravityOff>
        </gazebo>

        <gazebo reference="left_wheel">
                <mu1 value="1"/>
                <mu2 value="1"/>
                <kp  value="1000000.0" />
                <kd  value="100.0" />
                <fdir1 value="1 0 0"/>
                <material>Gazebo/Black</material>
                <turnGravityOff>false</turnGravityOff>
                <dampingFactor>0.005</dampingFactor>    <!-- Link velocity damping factor -->
        </gazebo>

        <gazebo reference="right_wheel">
                <mu1 value="1"/>
                <mu2 value="1"/>
                <kp  value="1000000.0" />
                <kd  value="100.0" />
                <fdir1 value="1 0 0"/>
                <material>Gazebo/Black</material>
                <turnGravityOff>false</turnGravityOff>
                <dampingFactor>0.005</dampingFactor>    <!-- Link velocity damping factor -->
        </gazebo>
        <gazebo reference="base_link">
                <material>Gazebo/Red </material>
        </gazebo>
        <gazebo reference="caster_wheel">
                <mu1 value="0"/>
                <mu2 value="0"/>
                <fdir1 value="1 0 0"/>
                <material>Gazebo/Red </material>
                <dampingFactor>0.01</dampingFactor>
        </gazebo>
        <gazebo reference="camera">
                <material> Gazebo/Blue </material>
        </gazebo>
        <gazebo reference="laser_scanner">
                <material> Gazebo/Yellow </material>
        </gazebo>
        <!-- Loading gazebo-ros-control plugin (works as an interface between transmissions and simulated actuators in gazebo) -->
        <gazebo>
                <plugin name="gazebo_ros_control" filename="libgazebo_ros_control.so">
                        <robotNamespace>/catbot</robotNamespace>
                        <controlPeriod> 0.001 </controlPeriod>
                </plugin>
        </gazebo>
</robot>
